<sdf version='1.9'>
  <model name='pick_and_drop_arm'>
    <joint name='world_to_base' type='fixed'>
      <pose relative_to='__model__'>0 0 0 0 0 0</pose>
      <parent>world</parent>
      <child>base_link</child>
    </joint>
    <link name='base_link'>
      <pose relative_to='world_to_base'>0 0 0 0 0 0</pose>
      <inertial>
        <pose>0 0 -0.05 0 0 0</pose>
        <mass>20</mass>
        <inertia>
          <ixx>0.02</ixx>
          <ixy>0</ixy>
          <ixz>0</ixz>
          <iyy>0.02</iyy>
          <iyz>0</iyz>
          <izz>0.02</izz>
        </inertia>
      </inertial>
      <collision name='base_link_collision'>
        <pose>0 0 0 0 0 0</pose>
        <geometry>
          <mesh>
            <scale>1 1 1</scale>
            <uri>model://pick_and_drop/meshes/base.dae</uri>
          </mesh>
        </geometry>
      </collision>
      <visual name='base_link_visual'>
        <pose>0 0 0 0 0 0</pose>
        <geometry>
          <mesh>
            <scale>1 1 1</scale>
            <uri>model://pick_and_drop/meshes/base.dae</uri>
          </mesh>
        </geometry>
        <material>
            <ambient>0.7 0.7 0.7 1</ambient>
            <diffuse>0.8 0.8 0.8 1</diffuse>
            <specular>0.2 0.2 0.2 1</specular>
        </material>
      </visual>
    </link>
    <joint name='base_joint' type='revolute'>
      <pose relative_to='base_link'>0 0 0.1 0 0 0</pose>
      <parent>base_link</parent>
      <child>link1</child>
      <axis>
        <xyz>0 0 1</xyz>
        <limit>
          <lower>-3.1400000000000001</lower>
          <upper>3.1400000000000001</upper>
          <effort>800</effort>
          <velocity>1</velocity>
        </limit>
        <dynamics>
          <spring_reference>0</spring_reference>
          <spring_stiffness>0</spring_stiffness>
        </dynamics>
      </axis>
    </joint>
    <link name='link1'>
      <pose relative_to='base_joint'>0 0 0 0 0 0</pose>
      <inertial>
        <pose>0 0 0 0 0 0</pose>
        <mass>1</mass>
        <inertia>
          <ixx>0.01</ixx>
          <ixy>0</ixy>
          <ixz>0</ixz>
          <iyy>0.01</iyy>
          <iyz>0</iyz>
          <izz>0.01</izz>
        </inertia>
      </inertial>
      <collision name='link1_collision'>
        <pose>0 0 0 0 0 0</pose>
        <geometry>
          <mesh>
            <scale>1 1 1</scale>
            <uri>model://pick_and_drop/meshes/1.dae</uri>
          </mesh>
        </geometry>
      </collision>
      <visual name='link1_visual'>
        <pose>0 0 0 0 0 0</pose>
        <geometry>
          <mesh>
            <scale>1 1 1</scale>
            <uri>model://pick_and_drop/meshes/1.dae</uri>
          </mesh>
        </geometry>
        <material>
            <ambient>0.7 0.7 0.7 1</ambient>
            <diffuse>0.8 0.8 0.8 1</diffuse>
            <specular>0.2 0.2 0.2 1</specular>
        </material>
      </visual>
    </link>
    <joint name='joint1' type='revolute'>
      <pose relative_to='link1'>0 0 1.67744 0 0 0</pose>
      <parent>link1</parent>
      <child>arm1</child>
      <axis>
        <xyz>1 0 0</xyz>
        <limit>
          <lower>-1.5700000000000001</lower>
          <upper>1.5700000000000001</upper>
          <effort>500</effort>
          <velocity>1</velocity>
        </limit>
        <dynamics>
          <damping>15.0</damping>
          <friction>3.0</friction>
          <spring_reference>0</spring_reference>
          <spring_stiffness>0</spring_stiffness>
        </dynamics>
      </axis>
    </joint>
    <link name='arm1'>
      <pose relative_to='joint1'>0 0 0 0 0 0</pose>
      <inertial>
        <pose>0 0 0 0 0 0</pose>
        <mass>1</mass>
        <inertia>
          <ixx>0.01</ixx>
          <ixy>0</ixy>
          <ixz>0</ixz>
          <iyy>0.01</iyy>
          <iyz>0</iyz>
          <izz>0.01</izz>
        </inertia>
      </inertial>
      <collision name='arm1_collision'>
        <pose>0 0 0 0 0 0</pose>
        <geometry>
          <mesh>
            <scale>1 1 1</scale>
            <uri>model://pick_and_drop/meshes/arm1.dae</uri>
          </mesh>
        </geometry>
      </collision>
      <visual name='arm1_visual'>
        <pose>0 0 0 0 0 0</pose>
        <geometry>
          <mesh>
            <scale>1 1 1</scale>
            <uri>model://pick_and_drop/meshes/arm1.dae</uri>
          </mesh>
        </geometry>
        <material>
            <ambient>0.7 0.7 0.7 1</ambient>
            <diffuse>0.8 0.8 0.8 1</diffuse>
            <specular>0.2 0.2 0.2 1</specular>
        </material>
      </visual>
    </link>
    <joint name='joint2' type='revolute'>
      <pose relative_to='arm1'>0 2.05731 2.08253 0 0 0</pose>
      <parent>arm1</parent>
      <child>arm2</child>
      <axis>
        <xyz>1 0 0</xyz>
        <limit>
          <lower>-1.5700000000000001</lower>
          <upper>1.5700000000000001</upper>
          <effort>500</effort>
          <velocity>1</velocity>
        </limit>
        <dynamics>
          <damping>15.0</damping>
          <friction>3.0</friction>
          <spring_reference>0</spring_reference>
          <spring_stiffness>0</spring_stiffness>
        </dynamics>
      </axis>
    </joint>
    <link name='arm2'>
      <pose relative_to='joint2'>0 0 0 0 0 0</pose>
      <inertial>
        <pose>0 0 0 0 0 0</pose>
        <mass>1</mass>
        <inertia>
          <ixx>0.01</ixx>
          <ixy>0</ixy>
          <ixz>0</ixz>
          <iyy>0.01</iyy>
          <iyz>0</iyz>
          <izz>0.01</izz>
        </inertia>
      </inertial>
      <collision name='arm2_collision'>
        <pose>0 0 0 0 0 0</pose>
        <geometry>
          <mesh>
            <scale>1 1 1</scale>
            <uri>model://pick_and_drop/meshes/arm2.dae</uri>
          </mesh>
        </geometry>
      </collision>
      <visual name='arm2_visual'>
        <pose>0 0 0 0 0 0</pose>
        <geometry>
          <mesh>
            <scale>1 1 1</scale>
            <uri>model://pick_and_drop/meshes/arm2.dae</uri>
          </mesh>
        </geometry>
        <material>
            <ambient>0.7 0.7 0.7 1</ambient>
            <diffuse>0.8 0.8 0.8 1</diffuse>
            <specular>0.2 0.2 0.2 1</specular>
        </material>
      </visual>
    </link>
    <joint name='joint3' type='revolute'>
      <pose relative_to='arm2'>0 -2.041415 2.09397 0 0 0</pose>
      <parent>arm2</parent>
      <child>arm3</child>
      <axis>
        <xyz>1 0 0</xyz>
        <limit>
          <lower>-1.5700000000000001</lower>
          <upper>1.5700000000000001</upper>
          <effort>500</effort>
          <velocity>1</velocity>
        </limit>
        <dynamics>
          <damping>15.0</damping>
          <friction>3.0</friction>
          <spring_reference>0</spring_reference>
          <spring_stiffness>0</spring_stiffness>
        </dynamics>
      </axis>
    </joint>
    <link name='arm3'>
      <pose relative_to='joint3'>0 0 0 0 0 0</pose>
      <inertial>
        <pose>0 0 0 0 0 0</pose>
        <mass>1</mass>
        <inertia>
          <ixx>0.01</ixx>
          <ixy>0</ixy>
          <ixz>0</ixz>
          <iyy>0.01</iyy>
          <iyz>0</iyz>
          <izz>0.01</izz>
        </inertia>
      </inertial>
      <collision name='arm3_collision'>
        <pose>0 0 0 0 0 0</pose>
        <geometry>
          <mesh>
            <scale>1 1 1</scale>
            <uri>model://pick_and_drop/meshes/arm3.dae</uri>
          </mesh>
        </geometry>
      </collision>
      <visual name='arm3_visual'>
        <pose>0 0 0 0 0 0</pose>
        <geometry>
          <mesh>
            <scale>1 1 1</scale>
            <uri>model://pick_and_drop/meshes/arm3.dae</uri>
          </mesh>
        </geometry>
        <material>
            <ambient>0.7 0.7 0.7 1</ambient>
            <diffuse>0.8 0.8 0.8 1</diffuse>
            <specular>0.2 0.2 0.2 1</specular>
        </material>
      </visual>
    </link>
    <joint name='joint4' type='revolute'>
      <pose relative_to='arm3'>0 -2.104915 -0.30269 0 0 0</pose>
      <parent>arm3</parent>
      <child>wrist</child>
      <axis>
        <xyz>1 0 0</xyz>
        <limit>
          <lower>-1.5700000000000001</lower>
          <upper>1.5700000000000001</upper>
          <effort>500</effort>
          <velocity>1</velocity>
        </limit>
        <dynamics>
          <damping>15.0</damping>
          <friction>3.0</friction>
          <spring_reference>0</spring_reference>
          <spring_stiffness>0</spring_stiffness>
        </dynamics>
      </axis>
    </joint>
    <link name='wrist'>
      <pose relative_to='joint4'>0 0 0 0 0 0</pose>
      <inertial>
        <pose>0 0 0 0 0 0</pose>
        <mass>0.5</mass>
        <inertia>
          <ixx>0.0050000000000000001</ixx>
          <ixy>0</ixy>
          <ixz>0</ixz>
          <iyy>0.0050000000000000001</iyy>
          <iyz>0</iyz>
          <izz>0.0050000000000000001</izz>
        </inertia>
      </inertial>
      <collision name='wrist_collision'>
        <pose>0 0 0 0 0 0</pose>
        <geometry>
          <mesh>
            <scale>1 1 1</scale>
            <uri>model://pick_and_drop/meshes/wrist.dae</uri>
          </mesh>
        </geometry>
      </collision>
      <visual name='wrist_visual'>
        <pose>0 0 0 0 0 0</pose>
        <geometry>
          <mesh>
            <scale>1 1 1</scale>
            <uri>model://pick_and_drop/meshes/wrist.dae</uri>
          </mesh>
        </geometry>
        <material>
            <ambient>0.7 0.7 0.7 1</ambient>
            <diffuse>0.8 0.8 0.8 1</diffuse>
            <specular>0.2 0.2 0.2 1</specular>
        </material>
      </visual>
    </link>
    <joint name='finger1_joint' type='revolute'>
      <pose relative_to='wrist'>0.005756 -1.4504 -0.85021 0 0 0</pose>
      <parent>wrist</parent>
      <child>finger1</child>
      <axis>
        <xyz>1 0 0</xyz>
        <limit>
          <lower>0</lower>
          <upper>0.80000000000000004</upper>
          <effort>100</effort>
          <velocity>1</velocity>
        </limit>
        <dynamics>
          <damping>0.5</damping>
          <friction>0.05</friction>
          <spring_reference>0</spring_reference>
          <spring_stiffness>0</spring_stiffness>
        </dynamics>
      </axis>
    </joint>
    <link name='finger1'>
      <pose relative_to='finger1_joint'>0 0 0 0 0 0</pose>
      <inertial>
        <pose>0 0 0 0 0 0</pose>
        <mass>0.20000000000000001</mass>
        <inertia>
          <ixx>0.002</ixx>
          <ixy>0</ixy>
          <ixz>0</ixz>
          <iyy>0.002</iyy>
          <iyz>0</iyz>
          <izz>0.002</izz>
        </inertia>
      </inertial>
      <collision name='finger1_collision'>
        <pose>0 0 0 0 0 0</pose>
        <geometry>
          <mesh>
            <scale>1 1 1</scale>
            <uri>model://pick_and_drop/meshes/finger1.dae</uri>
          </mesh>
        </geometry>
      </collision>
      <visual name='finger1_visual'>
        <pose>0 0 0 0 0 0</pose>
        <geometry>
          <mesh>
            <scale>1 1 1</scale>
            <uri>model://pick_and_drop/meshes/finger1.dae</uri>
          </mesh>
        </geometry>
        <material>
            <ambient>0.7 0.7 0.7 1</ambient>
            <diffuse>0.8 0.8 0.8 1</diffuse>
            <specular>0.2 0.2 0.2 1</specular>
        </material>
      </visual>
    </link>
    <joint name='finger2_joint' type='revolute'>
      <pose relative_to='wrist'>0.005756 -0.71318 -1.52533 0 0 0</pose>
      <parent>wrist</parent>
      <child>finger2</child>
      <axis>
        <xyz>-1 0 0</xyz>
        <limit>
          <lower>0</lower>
          <upper>0.80000000000000004</upper>
          <effort>100</effort>
          <velocity>1</velocity>
        </limit>
        <dynamics>
          <damping>0.5</damping>
          <friction>0.05</friction>
          <spring_reference>0</spring_reference>
          <spring_stiffness>0</spring_stiffness>
        </dynamics>
      </axis>
    </joint>
    <link name='finger2'>
      <pose relative_to='finger2_joint'>0 0 0 0 0 0</pose>
      <inertial>
        <pose>0 0 0 0 0 0</pose>
        <mass>0.20000000000000001</mass>
        <inertia>
          <ixx>0.002</ixx>
          <ixy>0</ixy>
          <ixz>0</ixz>
          <iyy>0.002</iyy>
          <iyz>0</iyz>
          <izz>0.002</izz>
        </inertia>
      </inertial>
      <collision name='finger2_collision'>
        <pose>0 0 0 0 0 0</pose>
        <geometry>
          <mesh>
            <scale>1 1 1</scale>
            <uri>model://pick_and_drop/meshes/finger2.dae</uri>
          </mesh>
        </geometry>
      </collision>
      <visual name='finger2_visual'>
        <pose>0 0 0 0 0 0</pose>
        <geometry>
          <mesh>
            <scale>1 1 1</scale>
            <uri>model://pick_and_drop/meshes/finger2.dae</uri>
          </mesh>
        </geometry>
        <material>
            <ambient>0.7 0.7 0.7 1</ambient>
            <diffuse>0.8 0.8 0.8 1</diffuse>
            <specular>0.2 0.2 0.2 1</specular>
        </material>
      </visual>
    </link>
    <!-- ================= CONTROLLERS ================= -->

    <!-- BASE -->
    <plugin filename="libignition-gazebo6-joint-position-controller-system.so"
            name="ignition::gazebo::systems::JointPositionController">
    <joint_name>base_joint</joint_name>
    <topic>/base_joint_cmd</topic>
    <p_gain>300</p_gain>
    <d_gain>30</d_gain>
    </plugin>

    <!-- ARM -->
    <plugin filename="libignition-gazebo6-joint-position-controller-system.so"
            name="ignition::gazebo::systems::JointPositionController">
    <joint_name>joint1</joint_name>
    <topic>/joint1_cmd</topic>

    <!-- ADD THIS -->
    <p_gain>100</p_gain>
    <i_gain>0</i_gain>
    <d_gain>10</d_gain>
    </plugin>

    <plugin filename="libignition-gazebo6-joint-position-controller-system.so"
            name="ignition::gazebo::systems::JointPositionController">
    <joint_name>joint2</joint_name>
    <topic>/joint2_cmd</topic>
    <p_gain>100</p_gain>
    <i_gain>0</i_gain>
    <d_gain>10</d_gain>
    </plugin>

    <plugin filename="libignition-gazebo6-joint-position-controller-system.so"
            name="ignition::gazebo::systems::JointPositionController">
    <joint_name>joint3</joint_name>
    <topic>/joint3_cmd</topic>
    <p_gain>100</p_gain>
    <i_gain>0</i_gain>
    <d_gain>10</d_gain>    
    </plugin>

    <plugin filename="libignition-gazebo6-joint-position-controller-system.so"
            name="ignition::gazebo::systems::JointPositionController">
    <joint_name>joint4</joint_name>
    <topic>/joint4_cmd</topic>
    <p_gain>100</p_gain>
    <i_gain>0</i_gain>
    <d_gain>10</d_gain>    
    </plugin>

    <!-- GRIPPER -->
    <plugin filename="libignition-gazebo6-joint-position-controller-system.so"
            name="ignition::gazebo::systems::JointPositionController">
    <joint_name>finger1_joint</joint_name>
    <topic>/finger1_cmd</topic>
    <p_gain>100</p_gain>
    <i_gain>0</i_gain>
    <d_gain>10</d_gain>
    </plugin>

    <plugin filename="libignition-gazebo6-joint-position-controller-system.so"
            name="ignition::gazebo::systems::JointPositionController">
    <joint_name>finger2_joint</joint_name>
    <topic>/finger2_cmd</topic>
    <p_gain>100</p_gain>
    <i_gain>0</i_gain>
    <d_gain>10</d_gain>
    </plugin>    
  </model>
</sdf>
